ERROR 7432  2022-11-13 07:29:44,551 django.request Internal Server Error: /api/edit/stations/
Traceback (most recent call last):
  File "/Users/bkohan/Documents/igs/SLM/.venv/lib/python3.7/site-packages/django/core/handlers/exception.py", line 47, in inner
    response = get_response(request)
  File "/Users/bkohan/Documents/igs/SLM/.venv/lib/python3.7/site-packages/django/core/handlers/base.py", line 181, in _get_response
    response = wrapped_callback(request, *callback_args, **callback_kwargs)
  File "/Users/bkohan/Documents/igs/SLM/.venv/lib/python3.7/site-packages/django/views/decorators/csrf.py", line 54, in wrapped_view
    return view_func(*args, **kwargs)
  File "/Users/bkohan/Documents/igs/SLM/.venv/lib/python3.7/site-packages/rest_framework/viewsets.py", line 125, in view
    return self.dispatch(request, *args, **kwargs)
  File "/Users/bkohan/Documents/igs/SLM/.venv/lib/python3.7/site-packages/rest_framework/views.py", line 509, in dispatch
    response = self.handle_exception(exc)
  File "/Users/bkohan/Documents/igs/SLM/.venv/lib/python3.7/site-packages/rest_framework/views.py", line 469, in handle_exception
    self.raise_uncaught_exception(exc)
  File "/Users/bkohan/Documents/igs/SLM/.venv/lib/python3.7/site-packages/rest_framework/views.py", line 480, in raise_uncaught_exception
    raise exc
  File "/Users/bkohan/Documents/igs/SLM/.venv/lib/python3.7/site-packages/rest_framework/views.py", line 506, in dispatch
    response = handler(request, *args, **kwargs)
  File "/Users/bkohan/Documents/igs/SLM/.venv/lib/python3.7/site-packages/rest_framework/mixins.py", line 18, in create
    serializer.is_valid(raise_exception=True)
  File "/Users/bkohan/Documents/igs/SLM/.venv/lib/python3.7/site-packages/rest_framework/serializers.py", line 227, in is_valid
    self._validated_data = self.run_validation(self.initial_data)
  File "/Users/bkohan/Documents/igs/SLM/.venv/lib/python3.7/site-packages/rest_framework/serializers.py", line 426, in run_validation
    value = self.to_internal_value(data)
  File "/Users/bkohan/Documents/igs/SLM/.venv/lib/python3.7/site-packages/rest_framework/serializers.py", line 479, in to_internal_value
    for field in fields:
  File "/Users/bkohan/Documents/igs/SLM/.venv/lib/python3.7/site-packages/rest_framework/serializers.py", line 362, in _writable_fields
    for field in self.fields.values():
  File "/Users/bkohan/Documents/igs/SLM/.venv/lib/python3.7/site-packages/django/utils/functional.py", line 48, in __get__
    res = instance.__dict__[self.name] = self.func(instance)
  File "/Users/bkohan/Documents/igs/SLM/.venv/lib/python3.7/site-packages/rest_framework/serializers.py", line 356, in fields
    for key, value in self.get_fields().items():
  File "/Users/bkohan/Documents/igs/SLM/.venv/lib/python3.7/site-packages/rest_framework/serializers.py", line 1052, in get_fields
    field_names = self.get_field_names(declared_fields, info)
  File "/Users/bkohan/Documents/igs/SLM/.venv/lib/python3.7/site-packages/rest_framework/serializers.py", line 1153, in get_field_names
    serializer_class=self.__class__.__name__
AssertionError: The field 'publish' was declared on serializer StationSerializer, but has not been included in the 'fields' option.
ERROR 7828  2022-11-13 07:31:26,568 django.request Internal Server Error: /api/edit/stations/
Traceback (most recent call last):
  File "/Users/bkohan/Documents/igs/SLM/.venv/lib/python3.7/site-packages/django/core/handlers/exception.py", line 47, in inner
    response = get_response(request)
  File "/Users/bkohan/Documents/igs/SLM/.venv/lib/python3.7/site-packages/django/core/handlers/base.py", line 181, in _get_response
    response = wrapped_callback(request, *callback_args, **callback_kwargs)
  File "/Users/bkohan/Documents/igs/SLM/.venv/lib/python3.7/site-packages/django/views/decorators/csrf.py", line 54, in wrapped_view
    return view_func(*args, **kwargs)
  File "/Users/bkohan/Documents/igs/SLM/.venv/lib/python3.7/site-packages/rest_framework/viewsets.py", line 125, in view
    return self.dispatch(request, *args, **kwargs)
  File "/Users/bkohan/Documents/igs/SLM/.venv/lib/python3.7/site-packages/rest_framework/views.py", line 509, in dispatch
    response = self.handle_exception(exc)
  File "/Users/bkohan/Documents/igs/SLM/.venv/lib/python3.7/site-packages/rest_framework/views.py", line 469, in handle_exception
    self.raise_uncaught_exception(exc)
  File "/Users/bkohan/Documents/igs/SLM/.venv/lib/python3.7/site-packages/rest_framework/views.py", line 480, in raise_uncaught_exception
    raise exc
  File "/Users/bkohan/Documents/igs/SLM/.venv/lib/python3.7/site-packages/rest_framework/views.py", line 506, in dispatch
    response = handler(request, *args, **kwargs)
  File "/Users/bkohan/Documents/igs/SLM/.venv/lib/python3.7/site-packages/rest_framework/mixins.py", line 19, in create
    self.perform_create(serializer)
  File "/Users/bkohan/Documents/igs/SLM/.venv/lib/python3.7/site-packages/rest_framework/mixins.py", line 24, in perform_create
    serializer.save()
  File "/Users/bkohan/Documents/igs/SLM/.venv/lib/python3.7/site-packages/rest_framework/serializers.py", line 212, in save
    self.instance = self.create(validated_data)
  File "/Users/bkohan/Documents/igs/SLM/slm/api/edit/serializers.py", line 75, in create
    del validated_data['key']
KeyError: 'key'
ERROR 8004  2022-11-13 07:32:04,491 django.request Internal Server Error: /api/edit/stations/
Traceback (most recent call last):
  File "/Users/bkohan/Documents/igs/SLM/.venv/lib/python3.7/site-packages/django/core/handlers/exception.py", line 47, in inner
    response = get_response(request)
  File "/Users/bkohan/Documents/igs/SLM/.venv/lib/python3.7/site-packages/django/core/handlers/base.py", line 181, in _get_response
    response = wrapped_callback(request, *callback_args, **callback_kwargs)
  File "/Users/bkohan/Documents/igs/SLM/.venv/lib/python3.7/site-packages/django/views/decorators/csrf.py", line 54, in wrapped_view
    return view_func(*args, **kwargs)
  File "/Users/bkohan/Documents/igs/SLM/.venv/lib/python3.7/site-packages/rest_framework/viewsets.py", line 125, in view
    return self.dispatch(request, *args, **kwargs)
  File "/Users/bkohan/Documents/igs/SLM/.venv/lib/python3.7/site-packages/rest_framework/views.py", line 509, in dispatch
    response = self.handle_exception(exc)
  File "/Users/bkohan/Documents/igs/SLM/.venv/lib/python3.7/site-packages/rest_framework/views.py", line 469, in handle_exception
    self.raise_uncaught_exception(exc)
  File "/Users/bkohan/Documents/igs/SLM/.venv/lib/python3.7/site-packages/rest_framework/views.py", line 480, in raise_uncaught_exception
    raise exc
  File "/Users/bkohan/Documents/igs/SLM/.venv/lib/python3.7/site-packages/rest_framework/views.py", line 506, in dispatch
    response = handler(request, *args, **kwargs)
  File "/Users/bkohan/Documents/igs/SLM/.venv/lib/python3.7/site-packages/rest_framework/mixins.py", line 19, in create
    self.perform_create(serializer)
  File "/Users/bkohan/Documents/igs/SLM/.venv/lib/python3.7/site-packages/rest_framework/mixins.py", line 24, in perform_create
    serializer.save()
  File "/Users/bkohan/Documents/igs/SLM/.venv/lib/python3.7/site-packages/rest_framework/serializers.py", line 212, in save
    self.instance = self.create(validated_data)
  File "/Users/bkohan/Documents/igs/SLM/slm/api/edit/serializers.py", line 73, in create
    for key in validated_data.keys():
RuntimeError: dictionary changed size during iteration
ERROR 8236  2022-11-13 07:32:55,031 django.request Internal Server Error: /api/edit/stations/
Traceback (most recent call last):
  File "/Users/bkohan/Documents/igs/SLM/.venv/lib/python3.7/site-packages/django/core/handlers/exception.py", line 47, in inner
    response = get_response(request)
  File "/Users/bkohan/Documents/igs/SLM/.venv/lib/python3.7/site-packages/django/core/handlers/base.py", line 181, in _get_response
    response = wrapped_callback(request, *callback_args, **callback_kwargs)
  File "/Users/bkohan/Documents/igs/SLM/.venv/lib/python3.7/site-packages/django/views/decorators/csrf.py", line 54, in wrapped_view
    return view_func(*args, **kwargs)
  File "/Users/bkohan/Documents/igs/SLM/.venv/lib/python3.7/site-packages/rest_framework/viewsets.py", line 125, in view
    return self.dispatch(request, *args, **kwargs)
  File "/Users/bkohan/Documents/igs/SLM/.venv/lib/python3.7/site-packages/rest_framework/views.py", line 509, in dispatch
    response = self.handle_exception(exc)
  File "/Users/bkohan/Documents/igs/SLM/.venv/lib/python3.7/site-packages/rest_framework/views.py", line 469, in handle_exception
    self.raise_uncaught_exception(exc)
  File "/Users/bkohan/Documents/igs/SLM/.venv/lib/python3.7/site-packages/rest_framework/views.py", line 480, in raise_uncaught_exception
    raise exc
  File "/Users/bkohan/Documents/igs/SLM/.venv/lib/python3.7/site-packages/rest_framework/views.py", line 506, in dispatch
    response = handler(request, *args, **kwargs)
  File "/Users/bkohan/Documents/igs/SLM/.venv/lib/python3.7/site-packages/rest_framework/mixins.py", line 19, in create
    self.perform_create(serializer)
  File "/Users/bkohan/Documents/igs/SLM/.venv/lib/python3.7/site-packages/rest_framework/mixins.py", line 24, in perform_create
    serializer.save()
  File "/Users/bkohan/Documents/igs/SLM/.venv/lib/python3.7/site-packages/rest_framework/serializers.py", line 212, in save
    self.instance = self.create(validated_data)
  File "/Users/bkohan/Documents/igs/SLM/slm/api/edit/serializers.py", line 94, in create
    agencies=validated_data['agencies']
KeyError: 'agencies'
WARNING 8409  2022-11-13 07:33:29,836 django.request Bad Request: /api/edit/stations/
WARNING 8666  2022-11-13 07:34:12,572 django.request Bad Request: /api/edit/stations/
WARNING 9228  2022-11-13 07:36:22,924 django.request Bad Request: /api/edit/stations/
WARNING 9399  2022-11-13 07:36:33,148 django.request Bad Request: /api/edit/stations/
WARNING 9470  2022-11-13 07:36:40,751 django.request Bad Request: /api/edit/stations/
WARNING 9711  2022-11-13 07:37:36,792 django.request Bad Request: /api/edit/stations/
WARNING 12318  2022-11-13 07:50:10,078 django.request Bad Request: /api/edit/stations/
WARNING 12577  2022-11-13 07:51:13,371 django.request Bad Request: /api/edit/stations/
WARNING 12669  2022-11-13 07:51:22,971 django.request Bad Request: /api/edit/stations/
WARNING 13070  2022-11-13 07:53:12,270 django.request Bad Request: /api/edit/stations/
WARNING 13185  2022-11-13 07:53:29,599 django.request Bad Request: /api/edit/stations/
WARNING 13270  2022-11-13 07:53:37,794 django.request Bad Request: /api/edit/stations/
WARNING 13390  2022-11-13 07:54:00,440 django.request Bad Request: /api/edit/stations/
WARNING 14087  2022-11-13 07:56:53,556 django.request Bad Request: /api/edit/stations/
WARNING 14326  2022-11-13 07:57:50,367 django.request Bad Request: /api/edit/stations/
WARNING 14437  2022-11-13 07:58:37,548 django.request Bad Request: /api/edit/stations/
WARNING 14666  2022-11-13 07:59:10,046 django.request Bad Request: /api/edit/stations/
WARNING 14803  2022-11-13 07:59:33,769 django.request Bad Request: /api/edit/stations/
WARNING 14993  2022-11-13 08:04:19,016 django.request Bad Request: /api/edit/stations/
ERROR 15920  2022-11-13 08:04:42,574 django.request Internal Server Error: /api/edit/stations/
Traceback (most recent call last):
  File "/Users/bkohan/Documents/igs/SLM/.venv/lib/python3.7/site-packages/django/core/handlers/exception.py", line 47, in inner
    response = get_response(request)
  File "/Users/bkohan/Documents/igs/SLM/.venv/lib/python3.7/site-packages/django/core/handlers/base.py", line 181, in _get_response
    response = wrapped_callback(request, *callback_args, **callback_kwargs)
  File "/Users/bkohan/Documents/igs/SLM/.venv/lib/python3.7/site-packages/django/views/decorators/csrf.py", line 54, in wrapped_view
    return view_func(*args, **kwargs)
  File "/Users/bkohan/Documents/igs/SLM/.venv/lib/python3.7/site-packages/rest_framework/viewsets.py", line 125, in view
    return self.dispatch(request, *args, **kwargs)
  File "/Users/bkohan/Documents/igs/SLM/.venv/lib/python3.7/site-packages/rest_framework/views.py", line 509, in dispatch
    response = self.handle_exception(exc)
  File "/Users/bkohan/Documents/igs/SLM/.venv/lib/python3.7/site-packages/rest_framework/views.py", line 469, in handle_exception
    self.raise_uncaught_exception(exc)
  File "/Users/bkohan/Documents/igs/SLM/.venv/lib/python3.7/site-packages/rest_framework/views.py", line 480, in raise_uncaught_exception
    raise exc
  File "/Users/bkohan/Documents/igs/SLM/.venv/lib/python3.7/site-packages/rest_framework/views.py", line 506, in dispatch
    response = handler(request, *args, **kwargs)
  File "/Users/bkohan/Documents/igs/SLM/slm/api/edit/views.py", line 215, in create
    return super().create(request, *args, **kwargs)
  File "/Users/bkohan/Documents/igs/SLM/.venv/lib/python3.7/site-packages/rest_framework/mixins.py", line 19, in create
    self.perform_create(serializer)
  File "/Users/bkohan/Documents/igs/SLM/slm/api/edit/views.py", line 219, in perform_create
    return super().perform_create(serializer)
  File "/Users/bkohan/Documents/igs/SLM/.venv/lib/python3.7/site-packages/rest_framework/mixins.py", line 24, in perform_create
    serializer.save()
  File "/Users/bkohan/Documents/igs/SLM/.venv/lib/python3.7/site-packages/rest_framework/serializers.py", line 212, in save
    self.instance = self.create(validated_data)
  File "/Users/bkohan/Documents/igs/SLM/slm/api/edit/serializers.py", line 74, in create
    from pprint import pprint
KeyError: 'agencies'
ERROR 16708  2022-11-13 08:08:16,836 django.request Internal Server Error: /api/edit/stations/
Traceback (most recent call last):
  File "/Users/bkohan/Documents/igs/SLM/.venv/lib/python3.7/site-packages/django/core/handlers/exception.py", line 47, in inner
    response = get_response(request)
  File "/Users/bkohan/Documents/igs/SLM/.venv/lib/python3.7/site-packages/django/core/handlers/base.py", line 181, in _get_response
    response = wrapped_callback(request, *callback_args, **callback_kwargs)
  File "/Users/bkohan/Documents/igs/SLM/.venv/lib/python3.7/site-packages/django/views/decorators/csrf.py", line 54, in wrapped_view
    return view_func(*args, **kwargs)
  File "/Users/bkohan/Documents/igs/SLM/.venv/lib/python3.7/site-packages/rest_framework/viewsets.py", line 125, in view
    return self.dispatch(request, *args, **kwargs)
  File "/Users/bkohan/Documents/igs/SLM/.venv/lib/python3.7/site-packages/rest_framework/views.py", line 509, in dispatch
    response = self.handle_exception(exc)
  File "/Users/bkohan/Documents/igs/SLM/.venv/lib/python3.7/site-packages/rest_framework/views.py", line 469, in handle_exception
    self.raise_uncaught_exception(exc)
  File "/Users/bkohan/Documents/igs/SLM/.venv/lib/python3.7/site-packages/rest_framework/views.py", line 480, in raise_uncaught_exception
    raise exc
  File "/Users/bkohan/Documents/igs/SLM/.venv/lib/python3.7/site-packages/rest_framework/views.py", line 506, in dispatch
    response = handler(request, *args, **kwargs)
  File "/Users/bkohan/Documents/igs/SLM/slm/api/edit/views.py", line 215, in create
    return super().create(request, *args, **kwargs)
  File "/Users/bkohan/Documents/igs/SLM/.venv/lib/python3.7/site-packages/rest_framework/mixins.py", line 19, in create
    self.perform_create(serializer)
  File "/Users/bkohan/Documents/igs/SLM/slm/api/edit/views.py", line 219, in perform_create
    return super().perform_create(serializer)
  File "/Users/bkohan/Documents/igs/SLM/.venv/lib/python3.7/site-packages/rest_framework/mixins.py", line 24, in perform_create
    serializer.save()
  File "/Users/bkohan/Documents/igs/SLM/.venv/lib/python3.7/site-packages/rest_framework/serializers.py", line 212, in save
    self.instance = self.create(validated_data)
  File "/Users/bkohan/Documents/igs/SLM/slm/api/edit/serializers.py", line 74, in create
    from pprint import pprint
KeyError: 'agencies'
ERROR 21543  2022-11-13 08:29:51,269 django.request Internal Server Error: /api/edit/stations/
Traceback (most recent call last):
  File "/Users/bkohan/Documents/igs/SLM/.venv/lib/python3.7/site-packages/django/core/handlers/exception.py", line 47, in inner
    response = get_response(request)
  File "/Users/bkohan/Documents/igs/SLM/.venv/lib/python3.7/site-packages/django/core/handlers/base.py", line 181, in _get_response
    response = wrapped_callback(request, *callback_args, **callback_kwargs)
  File "/Users/bkohan/Documents/igs/SLM/.venv/lib/python3.7/site-packages/django/views/decorators/csrf.py", line 54, in wrapped_view
    return view_func(*args, **kwargs)
  File "/Users/bkohan/Documents/igs/SLM/.venv/lib/python3.7/site-packages/rest_framework/viewsets.py", line 125, in view
    return self.dispatch(request, *args, **kwargs)
  File "/Users/bkohan/Documents/igs/SLM/.venv/lib/python3.7/site-packages/rest_framework/views.py", line 509, in dispatch
    response = self.handle_exception(exc)
  File "/Users/bkohan/Documents/igs/SLM/.venv/lib/python3.7/site-packages/rest_framework/views.py", line 469, in handle_exception
    self.raise_uncaught_exception(exc)
  File "/Users/bkohan/Documents/igs/SLM/.venv/lib/python3.7/site-packages/rest_framework/views.py", line 480, in raise_uncaught_exception
    raise exc
  File "/Users/bkohan/Documents/igs/SLM/.venv/lib/python3.7/site-packages/rest_framework/views.py", line 506, in dispatch
    response = handler(request, *args, **kwargs)
  File "/Users/bkohan/Documents/igs/SLM/.venv/lib/python3.7/site-packages/rest_framework/mixins.py", line 19, in create
    self.perform_create(serializer)
  File "/Users/bkohan/Documents/igs/SLM/.venv/lib/python3.7/site-packages/rest_framework/mixins.py", line 24, in perform_create
    serializer.save()
  File "/Users/bkohan/Documents/igs/SLM/.venv/lib/python3.7/site-packages/rest_framework/serializers.py", line 212, in save
    self.instance = self.create(validated_data)
  File "/Users/bkohan/Documents/igs/SLM/slm/api/edit/serializers.py", line 90, in create
    agencies=new_site.agencies
  File "/Users/bkohan/Documents/igs/SLM/.venv/lib/python3.7/site-packages/django/dispatch/dispatcher.py", line 182, in send
    for receiver in self._live_receivers(sender)
  File "/Users/bkohan/Documents/igs/SLM/.venv/lib/python3.7/site-packages/django/dispatch/dispatcher.py", line 182, in <listcomp>
    for receiver in self._live_receivers(sender)
  File "/Users/bkohan/Documents/igs/SLM/slm/tests/tests.py", line 47, in handle_signal
    self.signals.append(ReceivedSignal(name, signal, **kwargs))
NameError: name 'name' is not defined
ERROR 23816  2022-11-13 08:49:08,151 django.request Internal Server Error: /api/edit/stations/
Traceback (most recent call last):
  File "/Users/bkohan/Documents/igs/SLM/.venv/lib/python3.7/site-packages/django/core/handlers/exception.py", line 47, in inner
    response = get_response(request)
  File "/Users/bkohan/Documents/igs/SLM/.venv/lib/python3.7/site-packages/django/core/handlers/base.py", line 181, in _get_response
    response = wrapped_callback(request, *callback_args, **callback_kwargs)
  File "/Users/bkohan/Documents/igs/SLM/.venv/lib/python3.7/site-packages/django/views/decorators/csrf.py", line 54, in wrapped_view
    return view_func(*args, **kwargs)
  File "/Users/bkohan/Documents/igs/SLM/.venv/lib/python3.7/site-packages/rest_framework/viewsets.py", line 125, in view
    return self.dispatch(request, *args, **kwargs)
  File "/Users/bkohan/Documents/igs/SLM/.venv/lib/python3.7/site-packages/rest_framework/views.py", line 509, in dispatch
    response = self.handle_exception(exc)
  File "/Users/bkohan/Documents/igs/SLM/.venv/lib/python3.7/site-packages/rest_framework/views.py", line 469, in handle_exception
    self.raise_uncaught_exception(exc)
  File "/Users/bkohan/Documents/igs/SLM/.venv/lib/python3.7/site-packages/rest_framework/views.py", line 480, in raise_uncaught_exception
    raise exc
  File "/Users/bkohan/Documents/igs/SLM/.venv/lib/python3.7/site-packages/rest_framework/views.py", line 506, in dispatch
    response = handler(request, *args, **kwargs)
  File "/Users/bkohan/Documents/igs/SLM/.venv/lib/python3.7/site-packages/rest_framework/mixins.py", line 19, in create
    self.perform_create(serializer)
  File "/Users/bkohan/Documents/igs/SLM/.venv/lib/python3.7/site-packages/rest_framework/mixins.py", line 24, in perform_create
    serializer.save()
  File "/Users/bkohan/Documents/igs/SLM/.venv/lib/python3.7/site-packages/rest_framework/serializers.py", line 212, in save
    self.instance = self.create(validated_data)
  File "/Users/bkohan/Documents/igs/SLM/slm/api/edit/serializers.py", line 90, in create
    agencies=new_site.agencies.all()
  File "/Users/bkohan/Documents/igs/SLM/.venv/lib/python3.7/site-packages/django/dispatch/dispatcher.py", line 182, in send
    for receiver in self._live_receivers(sender)
  File "/Users/bkohan/Documents/igs/SLM/.venv/lib/python3.7/site-packages/django/dispatch/dispatcher.py", line 182, in <listcomp>
    for receiver in self._live_receivers(sender)
  File "/Users/bkohan/Documents/igs/SLM/slm/tests/tests.py", line 47, in handle_signal
    **kwargs
NameError: name 'name' is not defined
ERROR 25933  2022-11-13 08:49:12,994 django.request Internal Server Error: /api/edit/stations/
Traceback (most recent call last):
  File "/Users/bkohan/Documents/igs/SLM/.venv/lib/python3.7/site-packages/django/core/handlers/exception.py", line 47, in inner
    response = get_response(request)
  File "/Users/bkohan/Documents/igs/SLM/.venv/lib/python3.7/site-packages/django/core/handlers/base.py", line 181, in _get_response
    response = wrapped_callback(request, *callback_args, **callback_kwargs)
  File "/Users/bkohan/Documents/igs/SLM/.venv/lib/python3.7/site-packages/django/views/decorators/csrf.py", line 54, in wrapped_view
    return view_func(*args, **kwargs)
  File "/Users/bkohan/Documents/igs/SLM/.venv/lib/python3.7/site-packages/rest_framework/viewsets.py", line 125, in view
    return self.dispatch(request, *args, **kwargs)
  File "/Users/bkohan/Documents/igs/SLM/.venv/lib/python3.7/site-packages/rest_framework/views.py", line 509, in dispatch
    response = self.handle_exception(exc)
  File "/Users/bkohan/Documents/igs/SLM/.venv/lib/python3.7/site-packages/rest_framework/views.py", line 469, in handle_exception
    self.raise_uncaught_exception(exc)
  File "/Users/bkohan/Documents/igs/SLM/.venv/lib/python3.7/site-packages/rest_framework/views.py", line 480, in raise_uncaught_exception
    raise exc
  File "/Users/bkohan/Documents/igs/SLM/.venv/lib/python3.7/site-packages/rest_framework/views.py", line 506, in dispatch
    response = handler(request, *args, **kwargs)
  File "/Users/bkohan/Documents/igs/SLM/.venv/lib/python3.7/site-packages/rest_framework/mixins.py", line 19, in create
    self.perform_create(serializer)
  File "/Users/bkohan/Documents/igs/SLM/.venv/lib/python3.7/site-packages/rest_framework/mixins.py", line 24, in perform_create
    serializer.save()
  File "/Users/bkohan/Documents/igs/SLM/.venv/lib/python3.7/site-packages/rest_framework/serializers.py", line 212, in save
    self.instance = self.create(validated_data)
  File "/Users/bkohan/Documents/igs/SLM/slm/api/edit/serializers.py", line 90, in create
    agencies=new_site.agencies.all()
  File "/Users/bkohan/Documents/igs/SLM/.venv/lib/python3.7/site-packages/django/dispatch/dispatcher.py", line 182, in send
    for receiver in self._live_receivers(sender)
  File "/Users/bkohan/Documents/igs/SLM/.venv/lib/python3.7/site-packages/django/dispatch/dispatcher.py", line 182, in <listcomp>
    for receiver in self._live_receivers(sender)
  File "/Users/bkohan/Documents/igs/SLM/slm/tests/tests.py", line 47, in handle_signal
    **kwargs
TypeError: __new__() got an unexpected keyword argument 'site'
